Workbook

Sheet Publication Status Tracker NIE
F1: PLANNING & COLLABORATION (new) | G1: EXISTING COLUMNS (cleaned & standardised) | I1: PLANNING & COLLABORATION (new) | J1: EXISTING COLUMNS (cleaned & standardised) | M1: QUALITY & INDEXING — HIGH PRIORITY (new) | O1: EXISTING COLUMNS (cleaned & standardised) | Q1: QUALITY & INDEXING — HIGH PRIORITY (new) | S1: PLANNING & COLLABORATION (new)
A2: Title of the Paper | B2: Author(s) List | C2: Department | D2: Campus | E2: Corresponding Author | F2: Faculty Designation | G2: Status | H2: Start Date | I2: Submission Date | J2: Acceptance Date (Probable) | K2: Elapsed Days | L2: Publication Type | M2: Journal / Conference Name | N2: Impact Factor (IF) | O2: Scopus Quartile | P2: Web of Science (SCI/SCIE/ESCI) | Q2: DOI / URL | R2: Citation Count | S2: Citation Updated On | T2: Target Journal / Conference | U2: Rejection / Revision Count | V2: Research Area / Keywords | W2: Funding / Grant Title | X2: Funding Agency | Y2: Grant Amount (Rs. Lakhs) | Z2: External Collaborators | AA2: Student Co-authors | AB2: PhD Thesis Link | AC2: Review Notes / Comments
A3: Machine Learning for Bearing Health Monitoring: A Performance Evaluation with Vibration Data | B3: Prasanta Kumar Samal, Imran M Jamadar | C3: MECH | D3: South | E3: Ptrasanta Kumar Samal | F3: Assistant Professor | G3: Under Review | H3: 45736 | I3: 21/11/2025 | J3: 46203 | K3: =IF(AND(H3<>"",J3<>""),J3-H3,"") -> 467 | L3: Journal Article | N3: 0.71 | O3: Q3 | P3: Yes | U3: R2 | V3: Condition Monitoring of Bearing using Machine Learning | X3: None | AA3: None
A4: Synergistic Effects of Wood Filler – Glass/Carbon Fibers on the Tribological Behavior of Polypropylene Hybrid Composites | B4: H. V. Divya, T. P. Jeevan, T. G. Yashas Gowda & A. Anand | C4: MECH | D4: South | E4: Anand A | F4: Assistant Professor | G4: Published | H4: 45597 | J4: 45723 | K4: =IF(AND(H4<>"",J4<>""),J4-H4,"") -> 126 | L4: Journal Article | M4: Journal | O4: Q1 | P4: Yes
A5: Exploring the integration of renewable energy sources for sustainable charging infrastructure in electric vehicles | B5: R.A. Priya, Subrata Jana, Sri Harsha Grandhi, Saroj Kumar Nanda, Pappula Sampath Kumar, V. Vikram Athreya | C5: MECH | D5: South | E5: Vikram Athreya V | F5: Assistant Professor | G5: Published | H5: 45334 | I5: 22/01/2025 | J5: 45740 | K5: =IF(AND(H5<>"",J5<>""),J5-H5,"") -> 406 | L5: Book Chapter | M5: Hybrid and Advanced Technologies | O5: Q4 | P5: No | Q5: http://dx.doi.org/10.1201/9781003559139-52 | V5: EVs charging | X5: None
A6: Simulation and Optimisation of Automated Robot Workstation of Car Body-in-White using Process Simulate | B6: Vikram Athreya V, Sunil Gaekwad, Sharath Chandra N, Sanjay Gowda H M | C6: MECH | D6: South | E6: Vikram Athreya V | F6: Assistant Professor | G6: Published | H6: 45366 | I6: 45545 | J6: 45664 | K6: =IF(AND(H6<>"",J6<>""),J6-H6,"") -> 298 | L6: Conference Paper | M6: Intelligent Control, Robotics, and Industrial Automation: Proceedings of International Conference, RCAAI 2024 | O6: Q4 | P6: No | Q6: https://doi.org/10.1007/978-981-95-2901-8_3 | V6: Automation system for Automotive body manufacturing | X6: None
A7: Development of CNC Thread Milling Machine with Hobbing Head | B7: Sathyanidhi Acharya H R, Vikram Athreya V | C7: MECH | D7: South | E7: Vikram Athreya V | F7: Assistant Professor | G7: Published | H7: 45453 | J7: 45669 | K7: =IF(AND(H7<>"",J7<>""),J7-H7,"") -> 216 | L7: Conference Paper | O7: Q4
A8: Morphological Analysis of FDM parts subjected to Surface Treatment | B8: Sunil Gaekwad, Sharath Chandra N, Vikram Athreya V | C8: MECH | D8: South | E8: Vikram Athreya V | F8: Assistant Professor | G8: Published | H8: 45733 | J8: 45901 | K8: =IF(AND(H8<>"",J8<>""),J8-H8,"") -> 168 | L8: Journal Article | O8: Q1 | P8: Yes
A9: Water Salinity Concentration Detection using Photonic Crystal Sensor | B9: Shreya H C, Meena Y R, Preeta Sharan, and Sharath Chandra N | C9: MECH | D9: South | E9: Shreya H C | G9: Accepted | H9: 45658 | J9: 45708 | K9: =IF(AND(H9<>"",J9<>""),J9-H9,"") -> 50 | L9: Conference Paper | O9: Q4
A10: Multi-Level Smart Grid Using Naïve Bayes Classifier for Renewable Energy Integration | B10: Pavithra Goravi Sukumar, Balachandra parameshwariah, A. M. Prasad, Sharmila Nagaraju, Mallikarjunaswamy Srikantaswamy, Sharath Chandra N | C10: MECH | D10: South | E10: Pavithra Goravi Sukumar | G10: Accepted | H10: 45658 | J10: 45708 | K10: =IF(AND(H10<>"",J10<>""),J10-H10,"") -> 50 | L10: Journal Article | O10: Q3
A11: AI-Driven Intelligent Power Management for Optimized Renewable Energy Utilization | B11: Pavithra Goravi Sukumar, Chandana Chikkasiddaiah and Mallikarjunaswamy Srikantaswamy, Sharmila Nagaraju, Balachandra parameshwariah, Sharath Chandra N | C11: MECH | D11: South | E11: Pavithra Goravi Sukumar | G11: Accepted | H11: 45659 | J11: 45708 | K11: =IF(AND(H11<>"",J11<>""),J11-H11,"") -> 49 | L11: Journal Article | O11: Q2
A12: Prototype for Stress-based Viral Fever Prediction | B12: Anand Srivatsa, Fida Fareesha, Lekhana G, chandanashree yk, gowthami v | C12: ECE | D12: South | E12: Dr. Anand srivatsa | F12: Associate Professor | G12: Under Review | H12: 45895 | I12: 46003 | J12: 45931 | K12: =IF(AND(H12<>"",J12<>""),J12-H12,"") -> 36 | L12: Journal Article | M12: Journal (TASET) lanshscience.com
A13: Online Inspection of Sprocket using Cognex Vision Sensor IS2000 | B13: Dr. Prakash K R, VinodKumar H P, Ravalnath Bhat | C13: MECH | D13: South | E13: VinodKumar H P | G13: Submitted | H13: 45730 | J13: 45931 | K13: =IF(AND(H13<>"",J13<>""),J13-H13,"") -> 201 | L13: Conference Paper | O13: Q4
A14: A Novel Suction Cup System to Open Cardboard Box Corrugated Partition for Packing | B14: Hruthik P N, VinodKumar H P | C14: MECH | D14: South | E14: VinodKumar H P | G14: Submitted | H14: 45681 | J14: 45870 | K14: =IF(AND(H14<>"",J14<>""),J14-H14,"") -> 189 | L14: Conference Paper | O14: Q4
A15: Residual vibrations control of a 3D printed lightweight single link flexible manipulator. | B15: Imran M Jamadar, allwin yesuvadian R, Prasanta Kumar Samal, VinodKumar H P, Anand A | C15: MECH | D15: South | E15: Imran M Jamadar | F15: Professor | G15: Accepted | H15: 45748 | J15: 45931 | K15: =IF(AND(H15<>"",J15<>""),J15-H15,"") -> 183 | L15: Journal Article | M15: Sigma Journal of Engineering and Natural Sciences | N15: 0.6 | O15: Q4 | P15: Yes | Q15: 10.14744/sigma.2025.00167 | R15: 0 | S15: 31-03-2026 | U15: 1 | V15: Vibration control, 3D printing, PLC control, ANSYS | W15: State University Research Excellence | X15: SERB | Y15: 17.5 | AA15: PG Only | AB15: No
A16: A Study of Impact Toughness Behavior and High Cycle Fatigue Properties of Al-Li 8090 Alloy Processed by Cryorolling and Post-Deformation Annealing | B16: Yogesha K K, Subham Thapliyal, Amit Joshi, Saurabh Gairola, GK Kalavathi, MG Vasundhara, B Muralidhara, | C16: MECH | D16: South | E16: Amit Joshi | G16: Published | H16: 45543 | J16: 45714 | K16: =IF(AND(H16<>"",J16<>""),J16-H16,"") -> 171 | L16: Journal Article | O16: Q3
A17: Fatigue and Fracture Behaviour of 5052 Al Alloy Processed through Combined Severe Plastic Deformation Method | B17: Yogesha K K, Amit Joshi , Saurabh Gairola, R. Jayaganthan, G. M. Owolabi. | C17: MECH | D17: South | E17: Amit Joshi | G17: Under Review | H17: 45689 | J17: 45869 | K17: =IF(AND(H17<>"",J17<>""),J17-H17,"") -> 180 | L17: Book Chapter | O17: Q4
A18: "Sustainable Performance Enhancement of Polypropylene Composites Using Areca Husk Powder Reinforcement: A Comprehensive Analysis" | B18: Yogesha K K, Chandan M. | C18: MECH | D18: South | E18: Yogesha K K | F18: Professor | G18: Under Review | H18: 45722 | J18: 45900 | K18: =IF(AND(H18<>"",J18<>""),J18-H18,"") -> 178 | L18: Journal Article | O18: Q1
A19: "Optimizing Areca Husk Powder-Polypropylene Composites using Fuzzy AHP and TOPSIS" | B19: Yogesha K K, Chandan M | C19: MECH | D19: South | E19: Yogesha K K | F19: Professor | G19: Under Review | H19: 45748 | J19: 45930 | K19: =IF(AND(H19<>"",J19<>""),J19-H19,"") -> 182 | L19: Journal Article | O19: Q3
A20: A Comparative Analysis of Machine Learning Algorithms for Fault Classification in Cylindrical Roller Bearings | B20: Prasanta Kumar Samal, Imran M Jamadar | C20: MECH | D20: South | E20: Prasanta Kumar Samal | F20: Assistant Professor | G20: Published | H20: 45615 | J20: 45991 | K20: =IF(AND(H20<>"",J20<>""),J20-H20,"") -> 376 | L20: Journal Article | M20: FME Transactions | N20: 1.2 | O20: Q2 | P20: Yes | Q20: doi: 10.5937/fme2504681K | V20: Vibration based Condition monitoring of Cylinderical Bearing using machine learning | X20: None | AA20: PG Only
A21: Real-Time Autonomous Driving: A Unified Single-Stage Multi-Task Network Architecture | B21: Dr. S. RAGHAVENDRA,Dr. RAJALEKSHMI KISHORE, Mr. S. K. ABHILASH,Miss VENU MADHAV NOOKALA,Dr. MANISH VARUN YADAV | C21: ECE | D21: South | E21: Rajalekshmi Kishore | F21: Associate Professor | G21: Published | H21: 45817 | I21: 45721 | J21: 45868 | K21: =IF(AND(H21<>"",J21<>""),J21-H21,"") -> 51 | L21: Journal Article | M21: IEEE Access (Journal) | O21: Q1 | P21: Yes | Q21: Digital Object Identifier 10.1109/ACCESS.2025.3572107 | R21: 0 | AA21: None | AB21: No | AC21: https://ieeexplore.ieee.org/stamp/stamp.jsp?tp=&arnumber=11008573 Note: This journal article was published in collobaration with Manipal Institute of Technology , Manipal
A22: Wireless Vision: Human Object Detection Through Obstacles | B22: Rohit Kumar, Rajiv Chaura Priyansi , Aloy Anuja Mary and Rajalekshmi Kishore | C22: ECE | D22: South | E22: Rajalekshmi Kishore | F22: Associate Professor | G22: Published | H22: 45719 | J22: 45838 | K22: =IF(AND(H22<>"",J22<>""),J22-H22,"") -> 119 | L22: Conference Paper | M22: Proceedings of the 2025 International Conference on Advanced Research in Electronics and Communication Systems (ICARECS-2025) | O22: Q2 | P22: No | Q22: 10.2991/978-94-6463-754-0_43
A23: In-silico studies of 3-tert-butyl-7-[2-phenyl ethenyl]-4H-[1,3,4]thiadiazolo [2,3-c][1,2,4] triazin-4-one as a Potential SARS-CoV-2 Inhibitor: Insights from an experimental and computational approach | B23: Chandra, Lohith T.N., B. H. Gayathri, Mehran Feizi-Dehnayebi, Karthik V, Shamantha Kumar, Divya, M.A. Sridhar, M. Mahendra, Ghodsi Mohammadi Ziarani | C23: PHY | D23: South | E23: B. H. Gayathri | G23: Published | H23: 45588 | J23: 45709 | K23: =IF(AND(H23<>"",J23<>""),J23-H23,"") -> 121 | L23: Journal Article | O23: Q2 | P23: Yes
A24: Growth, and characterization of the nonlinear optical crystal 2’, 3’‑Di‑O‑acetyl‑5’‑deoxy‑5‑fluoro‑N4‑ (pentyloxycarbonyl) cytidine: structural, optical, thermal, electrical, and molecular docking studies | B24: Dhanushchandraguru H M, Hemaraju B C, Chandra, Vinay Kumar D C, Vinayakprasanna N Hegde , Manju V V, Deeksha K B and Yashas Gowda T G | C24: PHY | D24: South | E24: Hemaraju B C | G24: Published | H24: 45878 | J24: 45900 | K24: =IF(AND(H24<>"",J24<>""),J24-H24,"") -> 22 | L24: Journal Article | O24: Q2 | P24: Yes
A25: Eco-friendly Synthesis of BiVO4 Nanoparticles from Ipomoea Campanulata Leaf Extracts: Advances in Photocatalysis and Electrochemical Sensing | B25: Sunil Kumar K C, Chandra, Lakshmi Ranganatha V, Shivaganga G S, Soundarya T L, Nagaraju G, Mallikarjunaswamy C | C25: PHY | D25: South | E25: Chandra | G25: Published | H25: 45709 | J25: 45869 | K25: =IF(AND(H25<>"",J25<>""),J25-H25,"") -> 160 | L25: Journal Article | O25: Q2 | P25: Yes
A26: Comprehensive structural, electronic, and in-silico characterization of 1-phenyl-5-(m-tolyl)-1H-tetrazole as a potential steroidogenic factor-1 (SF-1) inhibitor candidate | B26: H.M. Dhanushchandraguru, B.C. Hemaraju, Chandra Vinay Kumar D C, B.S. Chethan, P. Akhileshwari, R. Preetham , M.P. Sadashiva | C26: PHY | D26: South | E26: B.C. Hemaraju | G26: Published | H26: 45903 | J26: 45900 | K26: =IF(AND(H26<>"",J26<>""),J26-H26,"") -> -3 | L26: Journal Article | O26: Q2 | P26: Yes
A27: Adaptability and Performance of WiNoC AcrossDifferent Mesh Sizes | B27: Shruthi R, Shashidhara H R, Manju Rajan, Bhargavi V, Anagha M A, Sagar D K | C27: ECE | D27: South | E27: Shruthi R | G27: Under Review | H27: 45731 | J27: 45930 | K27: =IF(AND(H27<>"",J27<>""),J27-H27,"") -> 199 | L27: Journal Article | O27: Q2
A28: Organic fluorine (C–F⋯F–C) mediated intermolecular interactions in (E)-3-(2,6-difluorophenyl)-1-(4-nitrophenyl)prop‐2-en-1-one: An intuition from an experimental and computational studies | B28: Lohith T.N, Sanjeeva S., Neetha S., Kishorkumar Sindogi, Mohd Sajid Ali, Rajiv Patel | C28: PHY | D28: South | E28: Dr. Lohith T. N. | G28: Published | H28: 45688 | J28: 45744 | K28: =IF(AND(H28<>"",J28<>""),J28-H28,"") -> 56 | L28: Journal Article | O28: Q2 | P28: Yes
A29: Structural elucidation, Hirshfeld surface analysis, DFT, and molecular docking studies of puckered compound: (6aS,12aR)-9-bromo-7,7-dimethyl-docking studies of puckered compound: (6aS,12aR)-9-bromo-7,7-dimethyl-6a,7,12,12a-tetrahydro-6H,13H-thiochromeno[3′,4′:5,6]thiopyrano[4,3-b]quinoline | B29: Anindita Bhattacharjee, Subram anya Hegde, Abdul Majeed Kurumbala, Vinay Kumar D. C., Nagarajaiah Honnappa, Mohd Sajid Ali, T. N. Lohith, M. B. Madhus udana Reddy | C29: PHY | D29: South | E29: Dr. Lohith T. N. | G29: Published | H29: 45666 | J29: 45736 | K29: =IF(AND(H29<>"",J29<>""),J29-H29,"") -> 70 | L29: Journal Article | O29: Q2 | P29: Yes
A30: Discovery of novel 1,2,3-Triazole hybrids derivatives as vasorelaxant agents: Molecular structure, Hirshfield surface, in-vivo and in-silico investigation by molecular docking simulation | B30: Yassine Rhazi, Ismail Bouadid, Mohamed Eddouks, Asmae Nakkabi, Usama Raza, Lohith T. N., Noemi Deak, Albert Soran, Mohamed El Yazidi, Marwa Alaqarbeh, Abdessamad Tounsi, Mohamed Anouar Harrad | C30: PHY | D30: South | E30: Mohamed Anouar Harrad | G30: Published | H30: 45665 | J30: 45729 | K30: =IF(AND(H30<>"",J30<>""),J30-H30,"") -> 64 | L30: Journal Article | O30: Q1 | P30: Yes
A31: Exploration of piperazine‐citral sulfonyl derivatives: antibacterial and in‐silico studies against methicillin‐resistant Staphylococcus aureus | B31: K. Nirusha, H. S. Nagendra Prasad, T. N. Lohith, P. Saravanan, L. Mallesha, A. P. Anand | C31: PHY | D31: South | E31: Nagendra Prasad H.S. | G31: Published | H31: 45646 | J31: 45700 | K31: =IF(AND(H31<>"",J31<>""),J31-H31,"") -> 54 | L31: Journal Article | O31: Q2 | P31: Yes
A32: Probing the Biological Activity of Isatin Derivatives Against Human Lung Cancer A549 Cells: Cytotoxicity, CT-DNA/BSA Binding, DFT/TD-DFT, Topology, ADME-Tox, Docking and Dynamic Simulations | B32: Ghodsi Mohammadi Ziarani, T.N. Lohith, Somayyeh Ghareghomi, Zahra Panahande, Majid Farsadrooh, Maryam Majidinia | C32: PHY | D32: South | E32: Mehran Feizi-Dehnayebi | G32: Published | H32: 45653 | J32: 45750 | K32: =IF(AND(H32<>"",J32<>""),J32-H32,"") -> 97 | L32: Journal Article | O32: Q1 | P32: Yes
A33: Interplay of weak intermolecular interactions (C-H⋅⋅⋅N and C-H⋅⋅⋅π) in pyrazole derivative: Crystal structure, Hirshfeld surface, DFT and in silico studies | B33: Madalambika, Lohith T. N., Neetha S, Vivek Hamse Kameshwar, Kothanahally S. Sharath Kumar, Mohd Sajid Ali, Hamad A. Al-Lohedan | C33: PHY | D33: South | E33: Dr. Lohith T. N. | G33: Revision Required | H33: 45750 | J33: 45807 | K33: =IF(AND(H33<>"",J33<>""),J33-H33,"") -> 57 | L33: Journal Article | O33: Q2 | P33: Yes
A34: Design, Synthesis, Molecular Docking, DFT Analysis, and Antifungal Evaluation of Novel different 1-((2-chlorophenyl)diphenylmethyl Analogues | B34: Shital Khinde, Rajesh Kancherla, H. Nagarajaiah, Lohith T. N., Perwez Alam | C34: PHY | D34: South | E34: Santosh Chhajed | G34: Under Review | H34: 45745 | J34: 45807 | K34: =IF(AND(H34<>"",J34<>""),J34-H34,"") -> 62 | L34: Journal Article | O34: Q2 | P34: Yes
A35: Probing the intermolecular interactions, binding affinity, charge density distribution of N-(3-chlorophenyl)-2-cyanoacetamide (NCPC) against Alzheimer’s disease: Insights of experimental and computational techniques | B35: Vinay Kumar D C., Nagaraja N., Shivaprasad C. M., Mohd Sajid Ali, Chethan B. S., Lohith T. N. | C35: PHY | D35: South | E35: Dr. Lohith T. N. | G35: Published | H35: 45743 | J35: 45838 | K35: =IF(AND(H35<>"",J35<>""),J35-H35,"") -> 95 | L35: Journal Article | O35: Q1 | P35: Yes
A36: Unveiling the structural and theoretical properties of 6-(2-fluoro-3-methylpyridin-4-yl)-2-(4-methoxyphenyl)-N-phenylquinoline-4-carboxamide compound as Sonic Hedgehog protein inhibitor: Synthesis, SCXRD, HSA, DFT, Docking and ADMET studies | B36: V Shalini, Vinay Kumar D C, Darshini Gowda, B. S Chethan, K. B Harsha, S. M Rajesh, K. S Rangappa | C36: PHY | D36: South | E36: K. S Rangappa | G36: Published | H36: 45632 | J36: 45680 | K36: =IF(AND(H36<>"",J36<>""),J36-H36,"") -> 48 | L36: Journal Article | O36: Q2
A37: A comprehensive investigation of 4-(4-chlorophenyl)-3-methyl-6,7,8,9-tetrahydroisoxazolo[5,4-b]quinolin-5(4H)-one as potential anticancer agent: Insights from computational and experimental results through crystal structure analysis | B37: Darshini Gowda, Vinay Kumar D C, Byresh Gowda, B.S. Chethan, K.B. Harsha, V. Shalini, M.S. Sudhanva, R. Shobith, K.S. Rangappa | C37: PHY | D37: South | E37: K.S. Rangappa | G37: Published | H37: 45477 | J37: 45676 | K37: =IF(AND(H37<>"",J37<>""),J37-H37,"") -> 199 | L37: Journal Article | O37: Q2
A38: Design and Characterization of Novel Isatin Derivatives: Insights into Crystal Structure, Intermolecular Interactions, and DFT Analysis | B38: Kishor Prasad S. Chethan B. S., Vinay Kumar D C, Pruthviraj K, Kenchanna S, Lokanath N. K. Manjunatha K and Sunil, K | C38: PHY | D38: South | E38: Sunil, K | G38: Published | H38: 45740 | J38: 45870 | K38: =IF(AND(H38<>"",J38<>""),J38-H38,"") -> 130 | L38: Journal Article | O38: Q2
A39: Structural analysis and computational studies of cyclopropane derivative as an anti- Alzheimer’s agent: Investigation of interactions by X-ray crystallography, DFT, molecular docking, and ADMET approaches | B39: S. M. Rajesh, Vinay Kumar D C, V. Shalini, K. B. Harsha, Darshini Gowda, K. S. Rangappa | C39: PHY | D39: South | E39: K. S. Rangappa | G39: Published | H39: 45730 | J39: 45788 | K39: =IF(AND(H39<>"",J39<>""),J39-H39,"") -> 58 | L39: Journal Article | O39: Q2 | P39: Yes
A40: Computational Design and Synthesis of Novel Acyl Hydrazone Derivatives Targeting Pyruvate Dehydrogenase Complex as Potent Antibacterial Agents Against E. coli | B40: Rashmi Shivakumar., Narendra Kumar, H. K., Narasimha M Beeraka., Vinay Kumar D C., Rangappa K. S., Ibrahim F. Rehan., Frantiˇsek Zigo., and Basappa Basappa. | C40: PHY | D40: South | E40: Basappa Basappa | G40: Revision Required | H40: 45719 | J40: 45808 | K40: =IF(AND(H40<>"",J40<>""),J40-H40,"") -> 89 | L40: Journal Article | O40: Q4
...

Sheet Read Me
B2: NIE Publication Status Tracker — User Guide
B4: PURPOSE | C4: Track all NIE faculty research publications. Supports pipeline monitoring and NIRF ranking strategy.
B5: BLUE COLUMNS | C5: Existing fields, cleaned and standardised from the original tracker.
B6: RED COLUMNS | C6: HIGH PRIORITY new fields for NIRF quality score: Journal Name, Impact Factor, DOI, Citation Count.
B7: GREEN COLUMNS | C7: New planning, collaboration, and funding fields. Fill progressively as information is available.
B8: DEPARTMENT | C8: Use standard codes only: CSE, ISE, ECE, MECH, CIVIL, EEE, MCA, MATHS, PHY, CHEM. Dropdown enforced.
B9: SCOPUS QUARTILE | C9: Now a separate column. Select Q1/Q2/Q3/Q4/Unspecified/Not Scopus from dropdown.
B10: WEB OF SCIENCE | C10: Select Yes or No. SCI, SCIE, and ESCI all qualify as Yes.
B11: IMPACT FACTOR | C11: Enter the journal IF at time of submission. Use 3 decimal places (e.g., 4.521).
B12: CITATION COUNT | C12: Update annually before NIRF submission. Log the date in Citation Updated On column.
B13: ELAPSED DAYS | C13: Auto-calculated from Start Date to Acceptance Date. Do not edit manually. | G13: V
B14: ANALYTICS TAB | C14: Auto-updating summaries by status, Scopus quartile, and department. Do not edit directly.
B15: DATA ENTRY TIP | C15: Use the dropdown menus wherever available to maintain consistency for Analytics.

Sheet Analytics
B2: NIE RESEARCH PUBLICATION DASHBOARD | W2: Dept | X2: Fac#
W3: CSE | X3: 39
B4: TOTAL PUBLISHED | H4: IN PIPELINE | L4: PUBLICATIONS / FACULTY | R4: Q1 + Q2 PAPERS | W4: ISE | X4: 29
B5: =COUNTIF('Publication Status Tracker NIE'!G:G,"Published") -> 216 | H5: =COUNTIF('Publication Status Tracker NIE'!G:G,"Accepted")+COUNTIF('Publication Status Tracker NIE'!G:G,"Under Review")+COUNTIF('Publication Status Tracker NIE'!G:G,"Submitted")+COUNTIF('Publication Status Tracker NIE'!G:G,"Revision Required") -> 260 | L5: =IFERROR(COUNTIF('Publication Status Tracker NIE'!G:G,"Published")/'Dept & Faculty'!G11,0) -> 27 | R5: =COUNTIF('Publication Status Tracker NIE'!O:O,"Q1")+COUNTIF('Publication Status Tracker NIE'!O:O,"Q2") -> 170 | W5: ECE | X5: 23
B6: papers across NIE | H6: accepted + under review + submitted | L6: vs target of 3.00 per year | R6: high-quality indexed papers | W6: MECH | X6: 31
W7: CIVIL | X7: 22
W8: EEE | X8: 15
B9: ▶ PUBLICATION PIPELINE | H9: ▶ QUALITY MIX | M9: ▶ PUBLICATION TYPE | R9: ▶ CAMPUS SPLIT | W9: MCA | X9: 12
B10: Draft / WIP | C10: =COUNTIF('Publication Status Tracker NIE'!G:G,"Draft / Work in Progress") -> 35 | D10: =IFERROR(C10/SUM(C10:C16)*100,0) -> 6.7567568 | H10: Q1 (Scopus) | I10: =COUNTIF('Publication Status Tracker NIE'!O:O,"Q1") -> 65 | J10: =IFERROR(I10/SUM(I10:I15)*100,0) -> 11.861314 | M10: Journal Article | N10: =COUNTIF('Publication Status Tracker NIE'!L:L,"Journal Article") -> 313 | O10: =IFERROR(N10/SUM(N10:N14)*100,0) -> 63.877551 | R10: South Campus | S10: =COUNTIF('Publication Status Tracker NIE'!D:D,"South") -> 321 | T10: =IFERROR(S10/SUM(S10:S11)*100,0) -> 61.494253 | W10: MATHS | X10: 12
B11: Submitted | C11: =COUNTIF('Publication Status Tracker NIE'!G:G,"Submitted") -> 41 | D11: =IFERROR(C11/SUM(C10:C16)*100,0) -> 7.9150579 | H11: Q2 (Scopus) | I11: =COUNTIF('Publication Status Tracker NIE'!O:O,"Q2") -> 105 | J11: =IFERROR(I11/SUM(I10:I15)*100,0) -> 19.160584 | M11: Conference Paper | N11: =COUNTIF('Publication Status Tracker NIE'!L:L,"Conference Paper") -> 110 | O11: =IFERROR(N11/SUM(N10:N14)*100,0) -> 22.44898 | R11: North Campus | S11: =COUNTIF('Publication Status Tracker NIE'!D:D,"North") -> 201 | T11: =IFERROR(S11/SUM(S10:S11)*100,0) -> 38.505747 | W11: PHY | X11: 9
B12: Under Review | C12: =COUNTIF('Publication Status Tracker NIE'!G:G,"Under Review") -> 83 | D12: =IFERROR(C12/SUM(C10:C16)*100,0) -> 16.023166 | H12: Q3 (Scopus) | I12: =COUNTIF('Publication Status Tracker NIE'!O:O,"Q3") -> 96 | J12: =IFERROR(I12/SUM(I10:I15)*100,0) -> 17.518248 | M12: Book Chapter | N12: =COUNTIF('Publication Status Tracker NIE'!L:L,"Book Chapter") -> 60 | O12: =IFERROR(N12/SUM(N10:N14)*100,0) -> 12.244898 | W12: CHEM | X12: 5
B13: Revision Reqd | C13: =COUNTIF('Publication Status Tracker NIE'!G:G,"Revision Required") -> 16 | D13: =IFERROR(C13/SUM(C10:C16)*100,0) -> 3.0888031 | H13: Q4 (Scopus) | I13: =COUNTIF('Publication Status Tracker NIE'!O:O,"Q4") -> 49 | J13: =IFERROR(I13/SUM(I10:I15)*100,0) -> 8.9416058 | M13: Review Article | N13: =COUNTIF('Publication Status Tracker NIE'!L:L,"Review Article") -> 4 | O13: =IFERROR(N13/SUM(N10:N14)*100,0) -> 0.81632653
B14: Accepted | C14: =COUNTIF('Publication Status Tracker NIE'!G:G,"Accepted") -> 120 | D14: =IFERROR(C14/SUM(C10:C16)*100,0) -> 23.166023 | H14: WoS (SCI/SCIE) | I14: =COUNTIF('Publication Status Tracker NIE'!P:P,"Yes") -> 146 | J14: =IFERROR(I14/SUM(I10:I15)*100,0) -> 26.642336 | M14: Other | N14: =COUNTIF('Publication Status Tracker NIE'!L:L,"Other Publication") -> 3 | O14: =IFERROR(N14/SUM(N10:N14)*100,0) -> 0.6122449
B15: Published | C15: =COUNTIF('Publication Status Tracker NIE'!G:G,"Published") -> 216 | D15: =IFERROR(C15/SUM(C10:C16)*100,0) -> 41.698842 | H15: Unspecified | I15: =COUNTIF('Publication Status Tracker NIE'!O:O,"Unspecified") -> 87 | J15: =IFERROR(I15/SUM(I10:I15)*100,0) -> 15.875912
B16: Rejected | C16: =COUNTIF('Publication Status Tracker NIE'!G:G,"Rejected") -> 7 | D16: =IFERROR(C16/SUM(C10:C16)*100,0) -> 1.3513514
B17: TOTAL | C17: =SUM(C10:C16) -> 518 | D17: 100%
B19: ▶ DEPARTMENT TARGET SCORECARD (Target: D4 publications per faculty per year)
C20: Department | D20: Faculty | E20: Target | F20: Published | G20: Pipeline | H20: Rate | I20: Gap | J20: Q1+Q2 | K20: Q1+Q2% | L20: Draft/WIP | M20: Progress % | N20: Status
C21: CSE | D21: 39 | E21: =D21*$D$4 -> 0 | F21: =COUNTIFS('Publication Status Tracker NIE'!C:C,C21,'Publication Status Tracker NIE'!G:G,"Published") -> 26 | G21: =COUNTIFS('Publication Status Tracker NIE'!C:C,C21,'Publication Status Tracker NIE'!G:G,"Accepted")+COUNTIFS('Publication Status Tracker NIE'!C:C,C21,'Publication Status Tracker NIE'!G:G,"Under Review")+COUNTIFS('Publication Status Tracker NIE'!C:C,C21,'Publication Status Tracker NIE'!G:G,"Submitted")+COUNTIFS('Publication Status Tracker NIE'!C:C,C21,'Publication Status Tracker NIE'!G:G,"Revision Required") -> 37 | H21: =IFERROR(F21/D21,0) -> 0.66666667 | I21: =E21-F21 -> -26 | J21: =COUNTIFS('Publication Status Tracker NIE'!C:C,C21,'Publication Status Tracker NIE'!O:O,"Q1")+COUNTIFS('Publication Status Tracker NIE'!C:C,C21,'Publication Status Tracker NIE'!O:O,"Q2") -> 13 | K21: =IFERROR(J21/F21*100,0) -> 50 | L21: =COUNTIFS('Publication Status Tracker NIE'!C:C,C21,'Publication Status Tracker NIE'!G:G,"Draft / Work in Progress") -> 6 | M21: =IFERROR(F21/E21*100,0) -> 0 | N21: =IF(H21>=$D$4,"✓ On Target",IF(H21>=$D$4*0.66,"⚠ Approaching",IF(H21>=$D$4*0.33,"↑ Improving","✗ Needs Action"))) -> ✓ On Target
C22: ISE | D22: 29 | E22: =D22*$D$4 -> 0 | F22: =COUNTIFS('Publication Status Tracker NIE'!C:C,C22,'Publication Status Tracker NIE'!G:G,"Published") -> 30 | G22: =COUNTIFS('Publication Status Tracker NIE'!C:C,C22,'Publication Status Tracker NIE'!G:G,"Accepted")+COUNTIFS('Publication Status Tracker NIE'!C:C,C22,'Publication Status Tracker NIE'!G:G,"Under Review")+COUNTIFS('Publication Status Tracker NIE'!C:C,C22,'Publication Status Tracker NIE'!G:G,"Submitted")+COUNTIFS('Publication Status Tracker NIE'!C:C,C22,'Publication Status Tracker NIE'!G:G,"Revision Required") -> 41 | H22: =IFERROR(F22/D22,0) -> 1.0344828 | I22: =E22-F22 -> -30 | J22: =COUNTIFS('Publication Status Tracker NIE'!C:C,C22,'Publication Status Tracker NIE'!O:O,"Q1")+COUNTIFS('Publication Status Tracker NIE'!C:C,C22,'Publication Status Tracker NIE'!O:O,"Q2") -> 16 | K22: =IFERROR(J22/F22*100,0) -> 53.333333 | L22: =COUNTIFS('Publication Status Tracker NIE'!C:C,C22,'Publication Status Tracker NIE'!G:G,"Draft / Work in Progress") -> 13 | M22: =IFERROR(F22/E22*100,0) -> 0 | N22: =IF(H22>=$D$4,"✓ On Target",IF(H22>=$D$4*0.66,"⚠ Approaching",IF(H22>=$D$4*0.33,"↑ Improving","✗ Needs Action"))) -> ✓ On Target
C23: ECE | D23: 23 | E23: =D23*$D$4 -> 0 | F23: =COUNTIFS('Publication Status Tracker NIE'!C:C,C23,'Publication Status Tracker NIE'!G:G,"Published") -> 29 | G23: =COUNTIFS('Publication Status Tracker NIE'!C:C,C23,'Publication Status Tracker NIE'!G:G,"Accepted")+COUNTIFS('Publication Status Tracker NIE'!C:C,C23,'Publication Status Tracker NIE'!G:G,"Under Review")+COUNTIFS('Publication Status Tracker NIE'!C:C,C23,'Publication Status Tracker NIE'!G:G,"Submitted")+COUNTIFS('Publication Status Tracker NIE'!C:C,C23,'Publication Status Tracker NIE'!G:G,"Revision Required") -> 49 | H23: =IFERROR(F23/D23,0) -> 1.2608696 | I23: =E23-F23 -> -29 | J23: =COUNTIFS('Publication Status Tracker NIE'!C:C,C23,'Publication Status Tracker NIE'!O:O,"Q1")+COUNTIFS('Publication Status Tracker NIE'!C:C,C23,'Publication Status Tracker NIE'!O:O,"Q2") -> 33 | K23: =IFERROR(J23/F23*100,0) -> 113.7931 | L23: =COUNTIFS('Publication Status Tracker NIE'!C:C,C23,'Publication Status Tracker NIE'!G:G,"Draft / Work in Progress") -> 9 | M23: =IFERROR(F23/E23*100,0) -> 0 | N23: =IF(H23>=$D$4,"✓ On Target",IF(H23>=$D$4*0.66,"⚠ Approaching",IF(H23>=$D$4*0.33,"↑ Improving","✗ Needs Action"))) -> ✓ On Target
C24: MECH | D24: 31 | E24: =D24*$D$4 -> 0 | F24: =COUNTIFS('Publication Status Tracker NIE'!C:C,C24,'Publication Status Tracker NIE'!G:G,"Published") -> 21 | G24: =COUNTIFS('Publication Status Tracker NIE'!C:C,C24,'Publication Status Tracker NIE'!G:G,"Accepted")+COUNTIFS('Publication Status Tracker NIE'!C:C,C24,'Publication Status Tracker NIE'!G:G,"Under Review")+COUNTIFS('Publication Status Tracker NIE'!C:C,C24,'Publication Status Tracker NIE'!G:G,"Submitted")+COUNTIFS('Publication Status Tracker NIE'!C:C,C24,'Publication Status Tracker NIE'!G:G,"Revision Required") -> 40 | H24: =IFERROR(F24/D24,0) -> 0.67741935 | I24: =E24-F24 -> -21 | J24: =COUNTIFS('Publication Status Tracker NIE'!C:C,C24,'Publication Status Tracker NIE'!O:O,"Q1")+COUNTIFS('Publication Status Tracker NIE'!C:C,C24,'Publication Status Tracker NIE'!O:O,"Q2") -> 17 | K24: =IFERROR(J24/F24*100,0) -> 80.952381 | L24: =COUNTIFS('Publication Status Tracker NIE'!C:C,C24,'Publication Status Tracker NIE'!G:G,"Draft / Work in Progress") -> 0 | M24: =IFERROR(F24/E24*100,0) -> 0 | N24: =IF(H24>=$D$4,"✓ On Target",IF(H24>=$D$4*0.66,"⚠ Approaching",IF(H24>=$D$4*0.33,"↑ Improving","✗ Needs Action"))) -> ✓ On Target
C25: CIVIL | D25: 22 | E25: =D25*$D$4 -> 0 | F25: =COUNTIFS('Publication Status Tracker NIE'!C:C,C25,'Publication Status Tracker NIE'!G:G,"Published") -> 12 | G25: =COUNTIFS('Publication Status Tracker NIE'!C:C,C25,'Publication Status Tracker NIE'!G:G,"Accepted")+COUNTIFS('Publication Status Tracker NIE'!C:C,C25,'Publication Status Tracker NIE'!G:G,"Under Review")+COUNTIFS('Publication Status Tracker NIE'!C:C,C25,'Publication Status Tracker NIE'!G:G,"Submitted")+COUNTIFS('Publication Status Tracker NIE'!C:C,C25,'Publication Status Tracker NIE'!G:G,"Revision Required") -> 33 | H25: =IFERROR(F25/D25,0) -> 0.54545455 | I25: =E25-F25 -> -12 | J25: =COUNTIFS('Publication Status Tracker NIE'!C:C,C25,'Publication Status Tracker NIE'!O:O,"Q1")+COUNTIFS('Publication Status Tracker NIE'!C:C,C25,'Publication Status Tracker NIE'!O:O,"Q2") -> 18 | K25: =IFERROR(J25/F25*100,0) -> 150 | L25: =COUNTIFS('Publication Status Tracker NIE'!C:C,C25,'Publication Status Tracker NIE'!G:G,"Draft / Work in Progress") -> 0 | M25: =IFERROR(F25/E25*100,0) -> 0 | N25: =IF(H25>=$D$4,"✓ On Target",IF(H25>=$D$4*0.66,"⚠ Approaching",IF(H25>=$D$4*0.33,"↑ Improving","✗ Needs Action"))) -> ✓ On Target
C26: EEE | D26: 15 | E26: =D26*$D$4 -> 0 | F26: =COUNTIFS('Publication Status Tracker NIE'!C:C,C26,'Publication Status Tracker NIE'!G:G,"Published") -> 9 | G26: =COUNTIFS('Publication Status Tracker NIE'!C:C,C26,'Publication Status Tracker NIE'!G:G,"Accepted")+COUNTIFS('Publication Status Tracker NIE'!C:C,C26,'Publication Status Tracker NIE'!G:G,"Under Review")+COUNTIFS('Publication Status Tracker NIE'!C:C,C26,'Publication Status Tracker NIE'!G:G,"Submitted")+COUNTIFS('Publication Status Tracker NIE'!C:C,C26,'Publication Status Tracker NIE'!G:G,"Revision Required") -> 15 | H26: =IFERROR(F26/D26,0) -> 0.6 | I26: =E26-F26 -> -9 | J26: =COUNTIFS('Publication Status Tracker NIE'!C:C,C26,'Publication Status Tracker NIE'!O:O,"Q1")+COUNTIFS('Publication Status Tracker NIE'!C:C,C26,'Publication Status Tracker NIE'!O:O,"Q2") -> 4 | K26: =IFERROR(J26/F26*100,0) -> 44.444444 | L26: =COUNTIFS('Publication Status Tracker NIE'!C:C,C26,'Publication Status Tracker NIE'!G:G,"Draft / Work in Progress") -> 3 | M26: =IFERROR(F26/E26*100,0) -> 0 | N26: =IF(H26>=$D$4,"✓ On Target",IF(H26>=$D$4*0.66,"⚠ Approaching",IF(H26>=$D$4*0.33,"↑ Improving","✗ Needs Action"))) -> ✓ On Target
C27: MCA | D27: 12 | E27: =D27*$D$4 -> 0 | F27: =COUNTIFS('Publication Status Tracker NIE'!C:C,C27,'Publication Status Tracker NIE'!G:G,"Published") -> 19 | G27: =COUNTIFS('Publication Status Tracker NIE'!C:C,C27,'Publication Status Tracker NIE'!G:G,"Accepted")+COUNTIFS('Publication Status Tracker NIE'!C:C,C27,'Publication Status Tracker NIE'!G:G,"Under Review")+COUNTIFS('Publication Status Tracker NIE'!C:C,C27,'Publication Status Tracker NIE'!G:G,"Submitted")+COUNTIFS('Publication Status Tracker NIE'!C:C,C27,'Publication Status Tracker NIE'!G:G,"Revision Required") -> 1 | H27: =IFERROR(F27/D27,0) -> 1.5833333 | I27: =E27-F27 -> -19 | J27: =COUNTIFS('Publication Status Tracker NIE'!C:C,C27,'Publication Status Tracker NIE'!O:O,"Q1")+COUNTIFS('Publication Status Tracker NIE'!C:C,C27,'Publication Status Tracker NIE'!O:O,"Q2") -> 0 | K27: =IFERROR(J27/F27*100,0) -> 0 | L27: =COUNTIFS('Publication Status Tracker NIE'!C:C,C27,'Publication Status Tracker NIE'!G:G,"Draft / Work in Progress") -> 2 | M27: =IFERROR(F27/E27*100,0) -> 0 | N27: =IF(H27>=$D$4,"✓ On Target",IF(H27>=$D$4*0.66,"⚠ Approaching",IF(H27>=$D$4*0.33,"↑ Improving","✗ Needs Action"))) -> ✓ On Target
C28: MATHS | D28: 12 | E28: =D28*$D$4 -> 0 | F28: =COUNTIFS('Publication Status Tracker NIE'!C:C,C28,'Publication Status Tracker NIE'!G:G,"Published") -> 9 | G28: =COUNTIFS('Publication Status Tracker NIE'!C:C,C28,'Publication Status Tracker NIE'!G:G,"Accepted")+COUNTIFS('Publication Status Tracker NIE'!C:C,C28,'Publication Status Tracker NIE'!G:G,"Under Review")+COUNTIFS('Publication Status Tracker NIE'!C:C,C28,'Publication Status Tracker NIE'!G:G,"Submitted")+COUNTIFS('Publication Status Tracker NIE'!C:C,C28,'Publication Status Tracker NIE'!G:G,"Revision Required") -> 17 | H28: =IFERROR(F28/D28,0) -> 0.75 | I28: =E28-F28 -> -9 | J28: =COUNTIFS('Publication Status Tracker NIE'!C:C,C28,'Publication Status Tracker NIE'!O:O,"Q1")+COUNTIFS('Publication Status Tracker NIE'!C:C,C28,'Publication Status Tracker NIE'!O:O,"Q2") -> 4 | K28: =IFERROR(J28/F28*100,0) -> 44.444444 | L28: =COUNTIFS('Publication Status Tracker NIE'!C:C,C28,'Publication Status Tracker NIE'!G:G,"Draft / Work in Progress") -> 2 | M28: =IFERROR(F28/E28*100,0) -> 0 | N28: =IF(H28>=$D$4,"✓ On Target",IF(H28>=$D$4*0.66,"⚠ Approaching",IF(H28>=$D$4*0.33,"↑ Improving","✗ Needs Action"))) -> ✓ On Target
C29: PHY | D29: 8 | E29: =D29*$D$4 -> 0 | F29: =COUNTIFS('Publication Status Tracker NIE'!C:C,C29,'Publication Status Tracker NIE'!G:G,"Published") -> 34 | G29: =COUNTIFS('Publication Status Tracker NIE'!C:C,C29,'Publication Status Tracker NIE'!G:G,"Accepted")+COUNTIFS('Publication Status Tracker NIE'!C:C,C29,'Publication Status Tracker NIE'!G:G,"Under Review")+COUNTIFS('Publication Status Tracker NIE'!C:C,C29,'Publication Status Tracker NIE'!G:G,"Submitted")+COUNTIFS('Publication Status Tracker NIE'!C:C,C29,'Publication Status Tracker NIE'!G:G,"Revision Required") -> 5 | H29: =IFERROR(F29/D29,0) -> 4.25 | I29: =E29-F29 -> -34 | J29: =COUNTIFS('Publication Status Tracker NIE'!C:C,C29,'Publication Status Tracker NIE'!O:O,"Q1")+COUNTIFS('Publication Status Tracker NIE'!C:C,C29,'Publication Status Tracker NIE'!O:O,"Q2") -> 36 | K29: =IFERROR(J29/F29*100,0) -> 105.88235 | L29: =COUNTIFS('Publication Status Tracker NIE'!C:C,C29,'Publication Status Tracker NIE'!G:G,"Draft / Work in Progress") -> 0 | M29: =IFERROR(F29/E29*100,0) -> 0 | N29: =IF(H29>=$D$4,"✓ On Target",IF(H29>=$D$4*0.66,"⚠ Approaching",IF(H29>=$D$4*0.33,"↑ Improving","✗ Needs Action"))) -> ✓ On Target
C30: CHEM | D30: 5 | E30: =D30*$D$4 -> 0 | F30: =COUNTIFS('Publication Status Tracker NIE'!C:C,C30,'Publication Status Tracker NIE'!G:G,"Published") -> 16 | G30: =COUNTIFS('Publication Status Tracker NIE'!C:C,C30,'Publication Status Tracker NIE'!G:G,"Accepted")+COUNTIFS('Publication Status Tracker NIE'!C:C,C30,'Publication Status Tracker NIE'!G:G,"Under Review")+COUNTIFS('Publication Status Tracker NIE'!C:C,C30,'Publication Status Tracker NIE'!G:G,"Submitted")+COUNTIFS('Publication Status Tracker NIE'!C:C,C30,'Publication Status Tracker NIE'!G:G,"Revision Required") -> 7 | H30: =IFERROR(F30/D30,0) -> 3.2 | I30: =E30-F30 -> -16 | J30: =COUNTIFS('Publication Status Tracker NIE'!C:C,C30,'Publication Status Tracker NIE'!O:O,"Q1")+COUNTIFS('Publication Status Tracker NIE'!C:C,C30,'Publication Status Tracker NIE'!O:O,"Q2") -> 19 | K30: =IFERROR(J30/F30*100,0) -> 118.75 | L30: =COUNTIFS('Publication Status Tracker NIE'!C:C,C30,'Publication Status Tracker NIE'!G:G,"Draft / Work in Progress") -> 0 | M30: =IFERROR(F30/E30*100,0) -> 0 | N30: =IF(H30>=$D$4,"✓ On Target",IF(H30>=$D$4*0.66,"⚠ Approaching",IF(H30>=$D$4*0.33,"↑ Improving","✗ Needs Action"))) -> ✓ On Target
C31: TOTAL / AVG | D31: =SUM(D21:D30) -> 196 | E31: =SUM(E21:E30) -> 0 | F31: =SUM(F21:F30) -> 205 | G31: =SUM(G21:G30) -> 245 | H31: =IFERROR(F31/D31,0) -> 1.0459184 | I31: =E31-F31 -> -205 | J31: =SUM(J21:J30) -> 160 | K31: =IFERROR(J31/F31*100,0) -> 78.04878 | L31: =SUM(L21:L30) -> 35 | M31: =IFERROR(F31/E31*100,0) -> 0
B32: ▶ CHARTS — DEPARTMENT PERFORMANCE
B43: ▶ QUALITY TRACKER — SCOPUS QUARTILE BY DEPARTMENT
C44: Department | D44: Total Papers | E44: Q1 | F44: Q2 | G44: Q3 | H44: Q4 | I44: Q1+Q2 | J44: Q1+Q2% | K44: WoS SCI/SCIE | W44: Dept | X44: Published | Y44: Target | Z44: Rate | AA44: Target
C45: =C21 -> CSE | D45: =F21+COUNTIFS('Publication Status Tracker NIE'!C:C,C45,'Publication Status Tracker NIE'!G:G,"Accepted") -> 45 | E45: =COUNTIFS('Publication Status Tracker NIE'!C:C,C45,'Publication Status Tracker NIE'!O:O,"Q1") -> 6 | F45: =COUNTIFS('Publication Status Tracker NIE'!C:C,C45,'Publication Status Tracker NIE'!O:O,"Q2") -> 7 | G45: =COUNTIFS('Publication Status Tracker NIE'!C:C,C45,'Publication Status Tracker NIE'!O:O,"Q3") -> 11 | H45: =COUNTIFS('Publication Status Tracker NIE'!C:C,C45,'Publication Status Tracker NIE'!O:O,"Q4") -> 2 | I45: =E45+F45 -> 13 | J45: =IFERROR((E45+F45)/D45*100,0) -> 28.888889 | K45: =COUNTIFS('Publication Status Tracker NIE'!C:C,C45,'Publication Status Tracker NIE'!P:P,"Yes") -> 14 | W45: =C21 -> CSE | X45: =F21 -> 26 | Y45: =E21 -> 0 | Z45: =H21 -> 0.66666667 | AA45: =$D$4
C46: =C22 -> ISE | D46: =F22+COUNTIFS('Publication Status Tracker NIE'!C:C,C46,'Publication Status Tracker NIE'!G:G,"Accepted") -> 47 | E46: =COUNTIFS('Publication Status Tracker NIE'!C:C,C46,'Publication Status Tracker NIE'!O:O,"Q1") -> 6 | F46: =COUNTIFS('Publication Status Tracker NIE'!C:C,C46,'Publication Status Tracker NIE'!O:O,"Q2") -> 10 | G46: =COUNTIFS('Publication Status Tracker NIE'!C:C,C46,'Publication Status Tracker NIE'!O:O,"Q3") -> 20 | H46: =COUNTIFS('Publication Status Tracker NIE'!C:C,C46,'Publication Status Tracker NIE'!O:O,"Q4") -> 7 | I46: =E46+F46 -> 16 | J46: =IFERROR((E46+F46)/D46*100,0) -> 34.042553 | K46: =COUNTIFS('Publication Status Tracker NIE'!C:C,C46,'Publication Status Tracker NIE'!P:P,"Yes") -> 10 | W46: =C22 -> ISE | X46: =F22 -> 30 | Y46: =E22 -> 0 | Z46: =H22 -> 1.0344828 | AA46: =$D$4
C47: =C23 -> ECE | D47: =F23+COUNTIFS('Publication Status Tracker NIE'!C:C,C47,'Publication Status Tracker NIE'!G:G,"Accepted") -> 43 | E47: =COUNTIFS('Publication Status Tracker NIE'!C:C,C47,'Publication Status Tracker NIE'!O:O,"Q1") -> 12 | F47: =COUNTIFS('Publication Status Tracker NIE'!C:C,C47,'Publication Status Tracker NIE'!O:O,"Q2") -> 21 | G47: =COUNTIFS('Publication Status Tracker NIE'!C:C,C47,'Publication Status Tracker NIE'!O:O,"Q3") -> 10 | H47: =COUNTIFS('Publication Status Tracker NIE'!C:C,C47,'Publication Status Tracker NIE'!O:O,"Q4") -> 4 | I47: =E47+F47 -> 33 | J47: =IFERROR((E47+F47)/D47*100,0) -> 76.744186 | K47: =COUNTIFS('Publication Status Tracker NIE'!C:C,C47,'Publication Status Tracker NIE'!P:P,"Yes") -> 18 | W47: =C23 -> ECE | X47: =F23 -> 29 | Y47: =E23 -> 0 | Z47: =H23 -> 1.2608696 | AA47: =$D$4
C48: =C24 -> MECH | D48: =F24+COUNTIFS('Publication Status Tracker NIE'!C:C,C48,'Publication Status Tracker NIE'!G:G,"Accepted") -> 42 | E48: =COUNTIFS('Publication Status Tracker NIE'!C:C,C48,'Publication Status Tracker NIE'!O:O,"Q1") -> 7 | F48: =COUNTIFS('Publication Status Tracker NIE'!C:C,C48,'Publication Status Tracker NIE'!O:O,"Q2") -> 10 | G48: =COUNTIFS('Publication Status Tracker NIE'!C:C,C48,'Publication Status Tracker NIE'!O:O,"Q3") -> 13 | H48: =COUNTIFS('Publication Status Tracker NIE'!C:C,C48,'Publication Status Tracker NIE'!O:O,"Q4") -> 20 | I48: =E48+F48 -> 17 | J48: =IFERROR((E48+F48)/D48*100,0) -> 40.47619 | K48: =COUNTIFS('Publication Status Tracker NIE'!C:C,C48,'Publication Status Tracker NIE'!P:P,"Yes") -> 16 | W48: =C24 -> MECH | X48: =F24 -> 21 | Y48: =E24 -> 0 | Z48: =H24 -> 0.67741935 | AA48: =$D$4
C49: =C25 -> CIVIL | D49: =F25+COUNTIFS('Publication Status Tracker NIE'!C:C,C49,'Publication Status Tracker NIE'!G:G,"Accepted") -> 31 | E49: =COUNTIFS('Publication Status Tracker NIE'!C:C,C49,'Publication Status Tracker NIE'!O:O,"Q1") -> 6 | F49: =COUNTIFS('Publication Status Tracker NIE'!C:C,C49,'Publication Status Tracker NIE'!O:O,"Q2") -> 12 | G49: =COUNTIFS('Publication Status Tracker NIE'!C:C,C49,'Publication Status Tracker NIE'!O:O,"Q3") -> 21 | H49: =COUNTIFS('Publication Status Tracker NIE'!C:C,C49,'Publication Status Tracker NIE'!O:O,"Q4") -> 1 | I49: =E49+F49 -> 18 | J49: =IFERROR((E49+F49)/D49*100,0) -> 58.064516 | K49: =COUNTIFS('Publication Status Tracker NIE'!C:C,C49,'Publication Status Tracker NIE'!P:P,"Yes") -> 17 | W49: =C25 -> CIVIL | X49: =F25 -> 12 | Y49: =E25 -> 0 | Z49: =H25 -> 0.54545455 | AA49: =$D$4
C50: =C26 -> EEE | D50: =F26+COUNTIFS('Publication Status Tracker NIE'!C:C,C50,'Publication Status Tracker NIE'!G:G,"Accepted") -> 21 | E50: =COUNTIFS('Publication Status Tracker NIE'!C:C,C50,'Publication Status Tracker NIE'!O:O,"Q1") -> 1 | F50: =COUNTIFS('Publication Status Tracker NIE'!C:C,C50,'Publication Status Tracker NIE'!O:O,"Q2") -> 3 | G50: =COUNTIFS('Publication Status Tracker NIE'!C:C,C50,'Publication Status Tracker NIE'!O:O,"Q3") -> 4 | H50: =COUNTIFS('Publication Status Tracker NIE'!C:C,C50,'Publication Status Tracker NIE'!O:O,"Q4") -> 7 | I50: =E50+F50 -> 4 | J50: =IFERROR((E50+F50)/D50*100,0) -> 19.047619 | K50: =COUNTIFS('Publication Status Tracker NIE'!C:C,C50,'Publication Status Tracker NIE'!P:P,"Yes") -> 9 | W50: =C26 -> EEE | X50: =F26 -> 9 | Y50: =E26 -> 0 | Z50: =H26 -> 0.6 | AA50: =$D$4
C51: =C27 -> MCA | D51: =F27+COUNTIFS('Publication Status Tracker NIE'!C:C,C51,'Publication Status Tracker NIE'!G:G,"Accepted") -> 20 | E51: =COUNTIFS('Publication Status Tracker NIE'!C:C,C51,'Publication Status Tracker NIE'!O:O,"Q1") -> 0 | F51: =COUNTIFS('Publication Status Tracker NIE'!C:C,C51,'Publication Status Tracker NIE'!O:O,"Q2") -> 0 | G51: =COUNTIFS('Publication Status Tracker NIE'!C:C,C51,'Publication Status Tracker NIE'!O:O,"Q3") -> 0 | H51: =COUNTIFS('Publication Status Tracker NIE'!C:C,C51,'Publication Status Tracker NIE'!O:O,"Q4") -> 2 | I51: =E51+F51 -> 0 | J51: =IFERROR((E51+F51)/D51*100,0) -> 0 | K51: =COUNTIFS('Publication Status Tracker NIE'!C:C,C51,'Publication Status Tracker NIE'!P:P,"Yes") -> 0 | W51: =C27 -> MCA | X51: =F27 -> 19 | Y51: =E27 -> 0 | Z51: =H27 -> 1.5833333 | AA51: =$D$4
C52: =C28 -> MATHS | D52: =F28+COUNTIFS('Publication Status Tracker NIE'!C:C,C52,'Publication Status Tracker NIE'!G:G,"Accepted") -> 15 | E52: =COUNTIFS('Publication Status Tracker NIE'!C:C,C52,'Publication Status Tracker NIE'!O:O,"Q1") -> 1 | F52: =COUNTIFS('Publication Status Tracker NIE'!C:C,C52,'Publication Status Tracker NIE'!O:O,"Q2") -> 3 | G52: =COUNTIFS('Publication Status Tracker NIE'!C:C,C52,'Publication Status Tracker NIE'!O:O,"Q3") -> 14 | H52: =COUNTIFS('Publication Status Tracker NIE'!C:C,C52,'Publication Status Tracker NIE'!O:O,"Q4") -> 3 | I52: =E52+F52 -> 4 | J52: =IFERROR((E52+F52)/D52*100,0) -> 26.666667 | K52: =COUNTIFS('Publication Status Tracker NIE'!C:C,C52,'Publication Status Tracker NIE'!P:P,"Yes") -> 8 | W52: =C28 -> MATHS | X52: =F28 -> 9 | Y52: =E28 -> 0 | Z52: =H28 -> 0.75 | AA52: =$D$4
...

Sheet Dept & Faculty
B2: Department | C2: Professors | D2: Assoc. Profs | E2: Asst. Profs | F2: On Contract | G2: Total
B3: CSE | C3: 5 | D3: 4 | E3: 30 | F3: 0 | G3: =SUM(C3:F3) -> 39
B4: ISE | C4: 5 | D4: 6 | E4: 18 | F4: 0 | G4: =SUM(C4:F4) -> 29
B5: MECH | C5: 3 | D5: 3 | E5: 23 | F5: 2 | G5: =SUM(C5:F5) -> 31
B6: ECE | C6: 0 | D6: 7 | E6: 12 | F6: 4 | G6: =SUM(C6:F6) -> 23
B7: CIVIL | C7: 2 | D7: 3 | E7: 9 | F7: 7 | G7: =SUM(C7:F7) -> 21
B8: EEE | C8: 2 | D8: 4 | E8: 5 | F8: 10 | G8: =SUM(C8:F8) -> 21
B9: MCA | C9: 1 | D9: 2 | E9: 1 | F9: 6 | G9: =SUM(C9:F9) -> 10
B10: MATHS | C10: 1 | D10: 3 | E10: 3 | F10: 5 | G10: =SUM(C10:F10) -> 12
B11: PHY | C11: 1 | D11: 2 | E11: 2 | F11: 3 | G11: =SUM(C11:F11) -> 8
B12: CHEM | C12: 0 | D12: 2 | E12: 3 | F12: 4 | G12: =SUM(C12:F12) -> 9
B13: TOTAL | C13: =SUM(C3:C12) -> 20 | D13: =SUM(D3:D12) -> 36 | E13: =SUM(E3:E12) -> 106 | F13: =SUM(F3:F12) -> 41 | G13: =SUM(G3:G12) -> 203
